Workbook

Sheet Cover
A1: ANGLO AMERICAN plc (LSE: AAL / JSE: AGL)
A2: 3-Year Growth Projections & Scenario Model — FY2026e to FY2028e
A4: Prepared for: Investment Committee
A5: Prepared: 14 June 2026 | Reporting currency: USD
A6: Basis: Standalone Anglo American plc, with Anglo Teck merger as a separate overlay
A8: Tabs:
A9: Summary | B9: Bull / Base / Bear EBITDA, FCF, net debt, EPS, valuation
A10: Dashboard | B10: Visual charts — EBITDA fan, net debt, FCF, EPS, segment split, copper sensitivity & deck
A11: Assumptions | B11: All inputs — commodity decks, oil/energy overlay, volumes, costs, finance, disposals, Teck terms
A12: Base / Bull / Bear | B12: Full scenario engines: price × volume EBITDA build → FCF → net debt
A13: Sensitivity | B13: Group EBITDA vs copper and iron ore price
A14: Teck overlay | B14: Illustrative Anglo Teck pro-forma EBITDA
A15: Sources | B15: Primary and external references
A17: DISCLAIMER: For informational purposes only; not investment advice and not a forecast of actual results. Anglo American reports in USD. Scenario figures are analyst assumptions marked (e) where estimated. Share prices obtained via search may be delayed; there is no live JSE/LME feed. Model is fully formula-driven — change blue inputs on 'Assumptions' to re-run.

Sheet Summary
A1: Anglo American — Scenario Summary (FY2026e–FY2028e)
A2: Standalone Anglo American plc. Teck merger shown separately on 'Teck overlay'. $m unless noted. (e)=estimate.
A4: Group underlying EBITDA ($m)
A5: Scenario | B5: 2025A | C5: 2026e | D5: 2027e | E5: 2028e
A6: Bull | B6: =Bull!C28 -> 6420.58 | C6: =Bull!D28 -> 9490.665 | D6: =Bull!E28 -> 10637 | E6: =Bull!F28 -> 11386.5
A7: Base | B7: =Base!C28 -> 6420.58 | C7: =Base!D28 -> 7009.27 | D7: =Base!E28 -> 6360.24 | E7: =Base!F28 -> 6734.54
A8: Bear | B8: =Bear!C28 -> 6420.58 | C8: =Bear!D28 -> 4803.8 | D8: =Bear!E28 -> 3552.37 | E8: =Bear!F28 -> 3419.47
A10: Attributable free cash flow ($m)
A11: Scenario | B11: 2025A | C11: 2026e | D11: 2027e | E11: 2028e
A12: Bull | B12: =Bull!C39 -> 812.3471 | C12: =Bull!D39 -> 2437.7998 | D12: =Bull!E39 -> 3863.415 | E12: =Bull!F39 -> 4934.63
A13: Base | B13: =Base!C39 -> 812.3471 | C13: =Base!D39 -> 899.3349 | D13: =Base!E39 -> 1164.4788 | E13: =Base!F39 -> 2030.805
A14: Bear | B14: =Bear!C39 -> 812.3471 | C14: =Bear!D39 -> -468.0565 | D14: =Bear!E39 -> -618.48101 | E14: =Bear!F39 -> -151.53695
A16: Closing net debt / (net cash) ($m)
A17: Scenario | B17: 2025A | C17: 2026e | D17: 2027e | E17: 2028e
A18: Bull | B18: =Bull!C44 -> 8571 | C18: =Bull!D44 -> 2840.6674 | D18: =Bull!E44 -> -3655.9473 | E18: =Bull!F44 -> -7624.6385
A19: Base | B19: =Base!C44 -> 8571 | C19: =Base!D44 -> 4103.2012 | D19: =Base!E44 -> 522.9273 | E19: =Base!F44 -> -1062.1444
A20: Bear | B20: =Bear!C44 -> 8571 | C20: =Bear!D44 -> 5225.3443 | D20: =Bear!E44 -> 3909.5559 | E20: =Bear!F44 -> 4119.3608
A22: Underlying EPS (cents) (e)
A23: Scenario | B23: 2025A | C23: 2026e | D23: 2027e | E23: 2028e
A24: Bull | B24: =Bull!C41 -> 81.205354 | C24: =Bull!D41 -> 156.93593 | D24: =Bull!E41 -> 192.28045 | E24: =Bull!F41 -> 214.27214
A25: Base | B25: =Base!C41 -> 81.205354 | C25: =Base!D41 -> 95.726722 | D25: =Base!E41 -> 85.227349 | E25: =Base!F41 -> 98.876081
A26: Bear | B26: =Bear!C41 -> 81.205354 | C26: =Bear!D41 -> 41.323824 | D26: =Bear!E41 -> 14.580885 | E26: =Bear!F41 -> 12.925451
A28: Net debt / EBITDA (x)
A29: Scenario | B29: 2025A | C29: 2026e | D29: 2027e | E29: 2028e
A30: Bull | B30: =Bull!C45 -> 1.3349261 | C30: =Bull!D45 -> 0.29931173 | D30: =Bull!E45 -> -0.34370098 | E30: =Bull!F45 -> -0.66962091
A31: Base | B31: =Base!C45 -> 1.3349261 | C31: =Base!D45 -> 0.58539636 | D31: =Base!E45 -> 0.082218171 | E31: =Base!F45 -> -0.15771595
A32: Bear | B32: =Bear!C45 -> 1.3349261 | C32: =Bear!D45 -> 1.0877523 | D32: =Bear!E45 -> 1.1005486 | E32: =Bear!F45 -> 1.2046782
A34: VALUATION CROSS-CHECK (on current EV)
A35: Equity value ($m) (e) | B35: =Assumptions!C54/100*Assumptions!C44*Assumptions!C55 -> 57875.958
A36: Current enterprise value ($m) (e) | B36: =B35+Assumptions!C56 -> 66446.958
A37: EV / EBITDA — 2026e (Bull/Base/Bear) | B37: =$B$36/Bull!D28 -> 7.0012963 | C37: =$B$36/Base!D28 -> 9.4798685 | D37: =$B$36/Bear!D28 -> 13.832166
A38: Note: equity uses LSE close 3,804p x 1,127m sh x GBPUSD (e). EV holds current net debt.

Sheet Dashboard
A1: Anglo American — Scenario Dashboard
A2: Bull / Base / Bear, FY2025A–FY2028e. Charts read live from the model — change blue inputs on 'Assumptions' to update. | T2: Chart data — FY2025 segment ($m)
T3: Copper | U3: =Base!C13 -> 3983.74
T4: Premium Iron Ore | U4: =Base!C22 -> 2875.84
T5: Manganese | U5: =Base!C24 -> 127
T6: Crop Nutrients | U6: =Base!C25 -> -66
T7: De Beers | U7: =Base!C26 -> -511
T12: Copper $/t | U12: 2025A | V12: 2026e | W12: 2027e | X12: 2028e
T13: Bull | U13: =Assumptions!C7 -> 9500 | V13: =Assumptions!D7 -> 13500 | W13: =Assumptions!E7 -> 14000 | X13: =Assumptions!F7 -> 14500
T14: Base | U14: =Assumptions!C8 -> 9500 | V14: =Assumptions!D8 -> 11500 | W14: =Assumptions!E8 -> 10000 | X14: =Assumptions!F8 -> 10500
T15: Bear | U15: =Assumptions!C9 -> 9500 | V15: =Assumptions!D9 -> 10000 | W15: =Assumptions!E9 -> 8200 | X15: =Assumptions!F9 -> 8000

Sheet Assumptions
A1: Anglo American plc (AAL / AGL) — Model Assumptions
A2: All figures illustrative. Blue = input (change for scenarios). Reporting currency USD ($m) unless noted. Prepared 14 June 2026.
A3: Numbers are scenario assumptions set by the analyst, anchored to FY2025 actuals + 2026-28 guidance + external commodity forecasts. Marked (e) where estimated.
A5: Assumption | B5: Unit | C5: 2025A | D5: 2026e | E5: 2027e | F5: 2028e
A6: COPPER — realised price (LME-linked), $/tonne
A7: Copper price — Bull | B7: $/t | C7: 9500 | D7: 13500 | E7: 14000 | F7: 14500
A8: Copper price — Base | B8: $/t | C8: 9500 | D8: 11500 | E8: 10000 | F8: 10500
A9: Copper price — Bear | B9: $/t | C9: 9500 | D9: 10000 | E9: 8200 | F9: 8000
A10: COPPER — production (attributable), kt
A11: Copper volume — Bull | B11: kt | C11: 695 | D11: 760 | E11: 810 | F11: 850
A12: Copper volume — Base | B12: kt | C12: 695 | D12: 730 | E12: 780 | F12: 820
A13: Copper volume — Bear | B13: kt | C13: 695 | D13: 700 | E13: 750 | F13: 790
A14: Copper unit cash cost (base, pre-energy) | B14: $/t | C14: 3768 | D14: 4250 | E14: 4200 | F14: 4150
A15: PREMIUM IRON ORE — realised price (FOB), $/tonne
A16: Iron ore price — Bull | B16: $/t | C16: 92.7 | D16: 95 | E16: 90 | F16: 88
A17: Iron ore price — Base | B17: $/t | C17: 92.7 | D17: 85 | E17: 78 | F17: 72
A18: Iron ore price — Bear | B18: $/t | C18: 92.7 | D18: 72 | E18: 60 | F18: 55
A19: PREMIUM IRON ORE — production, Mt
A20: Iron ore volume — Bull | B20: Mt | C20: 60.8 | D20: 59 | E20: 63 | F20: 62
A21: Iron ore volume — Base | B21: Mt | C21: 60.8 | D21: 57 | E21: 61 | F21: 60
A22: Iron ore volume — Bear | B22: Mt | C22: 60.8 | D22: 55 | E22: 59 | F22: 58
A23: Iron ore unit cash cost (base, pre-energy) | B23: $/t | C23: 45.4 | D23: 47 | E23: 47 | F23: 46
A24: IRAN WAR / ENERGY OVERLAY — oil price & cost sensitivity
A25: Brent oil price (avg) — Bull (de-escalates) | B25: $/bbl | C25: 72 | D25: 75 | E25: 72 | F25: 70
A26: Brent oil price (avg) — Base (fragile truce) | B26: $/bbl | C26: 72 | D26: 90 | E26: 80 | F26: 75
A27: Brent oil price (avg) — Bear (war into H2+) | B27: $/bbl | C27: 72 | D27: 120 | E27: 110 | F27: 95
A28: Baseline oil (pre-war, cost calib.) | B28: $/bbl | C28: 72
A29: Copper cost sensitivity | B29: $/t per $10/bbl | C29: 60
A30: Iron ore cost sensitivity | B30: $/t per $10/bbl | C30: 0.15
A31: OTHER SEGMENTS — underlying EBITDA, $m (scenario-flat)
A32: Manganese (40% Samancor JV) | B32: $m | C32: 127 | D32: 120 | E32: 120 | F32: 120
A33: Crop Nutrients / Woodsmith (pre-prod.) | B33: $m | C33: -66 | D33: -75 | E33: -80 | F33: -85
A34: De Beers (in disposal; exits FY26) | B34: $m | C34: -511 | D34: -350 | E34: 0 | F34: 0
A35: Corporate & other | B35: $m | C35: 11 | D35: -50 | E35: -50 | F35: -50
A36: CAPEX & FINANCE
A37: Capex (continuing ops) | B37: $m | C37: 3322 | D37: 3600 | E37: 3100 | F37: 2600
A38: Depreciation & amortisation (e) | B38: $m | C38: 2700
A39: Interest rate on opening net debt | B39: % | C39: 0.05
A40: Cash tax rate (on EBIT less interest) | B40: % | C40: 0.25
A41: Minority cash share (of EBITDA) | B41: % | C41: 0.13
...

Sheet Base
A1: Anglo American — Base case
A2: $m unless noted. Black = formula; green = link to Assumptions. EBITDA engine: Price x Volume less cash costs (incl. Iran energy overlay).
A4: Line | B4: Unit | C4: 2025A | D4: 2026e | E4: 2027e | F4: 2028e
A5: COPPER
A6: Production | B6: kt | C6: =Assumptions!C12 -> 695 | D6: =Assumptions!D12 -> 730 | E6: =Assumptions!E12 -> 780 | F6: =Assumptions!F12 -> 820
A7: Realised price | B7: $/t | C7: =Assumptions!C8 -> 9500 | D7: =Assumptions!D8 -> 11500 | E7: =Assumptions!E8 -> 10000 | F7: =Assumptions!F8 -> 10500
A8: Revenue | B8: $m | C8: =C6*C7/1000 -> 6602.5 | D8: =D6*D7/1000 -> 8395 | E8: =E6*E7/1000 -> 7800 | F8: =F6*F7/1000 -> 8610
A9: Unit cash cost (base) | B9: $/t | C9: =Assumptions!C14 -> 3768 | D9: =Assumptions!D14 -> 4250 | E9: =Assumptions!E14 -> 4200 | F9: =Assumptions!F14 -> 4150
A10: Energy overlay (Iran) | B10: $/t | C10: =MAX(0,(Assumptions!C26-Assumptions!C28)/10*Assumptions!C29) -> 0 | D10: =MAX(0,(Assumptions!D26-Assumptions!C28)/10*Assumptions!C29) -> 108 | E10: =MAX(0,(Assumptions!E26-Assumptions!C28)/10*Assumptions!C29) -> 48 | F10: =MAX(0,(Assumptions!F26-Assumptions!C28)/10*Assumptions!C29) -> 18
A11: Total unit cash cost | B11: $/t | C11: =C9+C10 -> 3768 | D11: =D9+D10 -> 4358 | E11: =E9+E10 -> 4248 | F11: =F9+F10 -> 4168
A12: Cash costs | B12: $m | C12: =C6*C11/1000 -> 2618.76 | D12: =D6*D11/1000 -> 3181.34 | E12: =E6*E11/1000 -> 3313.44 | F12: =F6*F11/1000 -> 3417.76
A13: Copper EBITDA | B13: $m | C13: =C8-C12 -> 3983.74 | D13: =D8-D12 -> 5213.66 | E13: =E8-E12 -> 4486.56 | F13: =F8-F12 -> 5192.24
A14: PREMIUM IRON ORE
A15: Production | B15: Mt | C15: =Assumptions!C21 -> 60.8 | D15: =Assumptions!D21 -> 57 | E15: =Assumptions!E21 -> 61 | F15: =Assumptions!F21 -> 60
A16: Realised price | B16: $/t | C16: =Assumptions!C17 -> 92.7 | D16: =Assumptions!D17 -> 85 | E16: =Assumptions!E17 -> 78 | F16: =Assumptions!F17 -> 72
A17: Revenue | B17: $m | C17: =C15*C16 -> 5636.16 | D17: =D15*D16 -> 4845 | E17: =E15*E16 -> 4758 | F17: =F15*F16 -> 4320
A18: Unit cash cost (base) | B18: $/t | C18: =Assumptions!C23 -> 45.4 | D18: =Assumptions!D23 -> 47 | E18: =Assumptions!E23 -> 47 | F18: =Assumptions!F23 -> 46
A19: Energy overlay (Iran) | B19: $/t | C19: =MAX(0,(Assumptions!C26-Assumptions!C28)/10*Assumptions!C30) -> 0 | D19: =MAX(0,(Assumptions!D26-Assumptions!C28)/10*Assumptions!C30) -> 0.27 | E19: =MAX(0,(Assumptions!E26-Assumptions!C28)/10*Assumptions!C30) -> 0.12 | F19: =MAX(0,(Assumptions!F26-Assumptions!C28)/10*Assumptions!C30) -> 0.045
A20: Total unit cash cost | B20: $/t | C20: =C18+C19 -> 45.4 | D20: =D18+D19 -> 47.27 | E20: =E18+E19 -> 47.12 | F20: =F18+F19 -> 46.045
A21: Cash costs | B21: $m | C21: =C15*C20 -> 2760.32 | D21: =D15*D20 -> 2694.39 | E21: =E15*E20 -> 2874.32 | F21: =F15*F20 -> 2762.7
A22: Iron ore EBITDA | B22: $m | C22: =C17-C21 -> 2875.84 | D22: =D17-D21 -> 2150.61 | E22: =E17-E21 -> 1883.68 | F22: =F17-F21 -> 1557.3
A23: OTHER SEGMENTS
A24: Manganese | B24: $m | C24: =Assumptions!C32 -> 127 | D24: =Assumptions!D32 -> 120 | E24: =Assumptions!E32 -> 120 | F24: =Assumptions!F32 -> 120
A25: Crop Nutrients / Woodsmith | B25: $m | C25: =Assumptions!C33 -> -66 | D25: =Assumptions!D33 -> -75 | E25: =Assumptions!E33 -> -80 | F25: =Assumptions!F33 -> -85
A26: De Beers | B26: $m | C26: =Assumptions!C34 -> -511 | D26: =Assumptions!D34 -> -350 | E26: =Assumptions!E34 -> 0 | F26: =Assumptions!F34 -> 0
A27: Corporate & other | B27: $m | C27: =Assumptions!C35 -> 11 | D27: =Assumptions!D35 -> -50 | E27: =Assumptions!E35 -> -50 | F27: =Assumptions!F35 -> -50
A28: GROUP UNDERLYING EBITDA | B28: $m | C28: =C13+C22+C24+C25+C26+C27 -> 6420.58 | D28: =D13+D22+D24+D25+D26+D27 -> 7009.27 | E28: =E13+E22+E24+E25+E26+E27 -> 6360.24 | F28: =F13+F22+F24+F25+F26+F27 -> 6734.54
A29: EBITDA growth (YoY) | B29: % | C29: - | D29: =D28/C28-1 -> 0.091687978 | E29: =E28/D28-1 -> -0.092595948 | F29: =F28/E28-1 -> 0.058849981
A30: CASH FLOW & NET DEBT
A31: Less: D&A (e) | B31: $m | C31: =-Assumptions!C38 -> -2700 | D31: =-Assumptions!C38 -> -2700 | E31: =-Assumptions!C38 -> -2700 | F31: =-Assumptions!C38 -> -2700
A32: Underlying EBIT | B32: $m | C32: =C28+C31 -> 3720.58 | D32: =D28+D31 -> 4309.27 | E32: =E28+E31 -> 3660.24 | F32: =F28+F31 -> 4034.54
A33: Opening net debt | B33: $m | C33: =Assumptions!C46 -> 8571 | D33: =Assumptions!C46 -> 8571 | E33: =D44 -> 4103.2012 | F33: =E44 -> 522.9273
A34: Net interest (e) | B34: $m | C34: =-MAX(0,C33)*Assumptions!C39 -> -428.55 | D34: =-MAX(0,D33)*Assumptions!C39 -> -428.55 | E34: =-MAX(0,E33)*Assumptions!C39 -> -205.16006 | F34: =-MAX(0,F33)*Assumptions!C39 -> -26.146365
A35: Cash tax (e) | B35: $m | C35: =-Assumptions!C40*MAX(0,C32+C34) -> -823.0075 | D35: =-Assumptions!C40*MAX(0,D32+D34) -> -970.18 | E35: =-Assumptions!C40*MAX(0,E32+E34) -> -863.76999 | F35: =-Assumptions!C40*MAX(0,F32+F34) -> -1002.0984
A36: Minorities (e) | B36: $m | C36: =-Assumptions!C41*C28 -> -834.6754 | D36: =-Assumptions!C41*D28 -> -911.2051 | E36: =-Assumptions!C41*E28 -> -826.8312 | F36: =-Assumptions!C41*F28 -> -875.4902
A37: Working capital / other | B37: $m | C37: =Assumptions!C42 -> -200 | D37: =Assumptions!C42 -> -200 | E37: =Assumptions!C42 -> -200 | F37: =Assumptions!C42 -> -200
A38: Less: capex | B38: $m | C38: =-Assumptions!C37 -> -3322 | D38: =-Assumptions!D37 -> -3600 | E38: =-Assumptions!E37 -> -3100 | F38: =-Assumptions!F37 -> -2600
A39: Attributable free cash flow | B39: $m | C39: =C28+C34+C35+C36+C37+C38 -> 812.3471 | D39: =D28+D34+D35+D36+D37+D38 -> 899.3349 | E39: =E28+E34+E35+E36+E37+E38 -> 1164.4788 | F39: =F28+F34+F35+F36+F37+F38 -> 2030.805
A40: Underlying earnings (e) | B40: $m | C40: =Assumptions!C43*MAX(0,C28+C31+C34) -> 915.18434 | D40: =Assumptions!C43*MAX(0,D28+D31+D34) -> 1078.8402 | E40: =Assumptions!C43*MAX(0,E28+E31+E34) -> 960.51222 | F40: =Assumptions!C43*MAX(0,F28+F31+F34) -> 1114.3334
A41: Underlying EPS (e) | B41: c | C41: =C40/Assumptions!C44*100 -> 81.205354 | D41: =D40/Assumptions!C44*100 -> 95.726722 | E41: =E40/Assumptions!C44*100 -> 85.227349 | F41: =F40/Assumptions!C44*100 -> 98.876081
...

Sheet Bull
A1: Anglo American — Bull case
A2: $m unless noted. Black = formula; green = link to Assumptions. EBITDA engine: Price x Volume less cash costs (incl. Iran energy overlay).
A4: Line | B4: Unit | C4: 2025A | D4: 2026e | E4: 2027e | F4: 2028e
A5: COPPER
A6: Production | B6: kt | C6: =Assumptions!C11 -> 695 | D6: =Assumptions!D11 -> 760 | E6: =Assumptions!E11 -> 810 | F6: =Assumptions!F11 -> 850
A7: Realised price | B7: $/t | C7: =Assumptions!C7 -> 9500 | D7: =Assumptions!D7 -> 13500 | E7: =Assumptions!E7 -> 14000 | F7: =Assumptions!F7 -> 14500
A8: Revenue | B8: $m | C8: =C6*C7/1000 -> 6602.5 | D8: =D6*D7/1000 -> 10260 | E8: =E6*E7/1000 -> 11340 | F8: =F6*F7/1000 -> 12325
A9: Unit cash cost (base) | B9: $/t | C9: =Assumptions!C14 -> 3768 | D9: =Assumptions!D14 -> 4250 | E9: =Assumptions!E14 -> 4200 | F9: =Assumptions!F14 -> 4150
A10: Energy overlay (Iran) | B10: $/t | C10: =MAX(0,(Assumptions!C25-Assumptions!C28)/10*Assumptions!C29) -> 0 | D10: =MAX(0,(Assumptions!D25-Assumptions!C28)/10*Assumptions!C29) -> 18 | E10: =MAX(0,(Assumptions!E25-Assumptions!C28)/10*Assumptions!C29) -> 0 | F10: =MAX(0,(Assumptions!F25-Assumptions!C28)/10*Assumptions!C29) -> 0
A11: Total unit cash cost | B11: $/t | C11: =C9+C10 -> 3768 | D11: =D9+D10 -> 4268 | E11: =E9+E10 -> 4200 | F11: =F9+F10 -> 4150
A12: Cash costs | B12: $m | C12: =C6*C11/1000 -> 2618.76 | D12: =D6*D11/1000 -> 3243.68 | E12: =E6*E11/1000 -> 3402 | F12: =F6*F11/1000 -> 3527.5
A13: Copper EBITDA | B13: $m | C13: =C8-C12 -> 3983.74 | D13: =D8-D12 -> 7016.32 | E13: =E8-E12 -> 7938 | F13: =F8-F12 -> 8797.5
A14: PREMIUM IRON ORE
A15: Production | B15: Mt | C15: =Assumptions!C20 -> 60.8 | D15: =Assumptions!D20 -> 59 | E15: =Assumptions!E20 -> 63 | F15: =Assumptions!F20 -> 62
A16: Realised price | B16: $/t | C16: =Assumptions!C16 -> 92.7 | D16: =Assumptions!D16 -> 95 | E16: =Assumptions!E16 -> 90 | F16: =Assumptions!F16 -> 88
A17: Revenue | B17: $m | C17: =C15*C16 -> 5636.16 | D17: =D15*D16 -> 5605 | E17: =E15*E16 -> 5670 | F17: =F15*F16 -> 5456
A18: Unit cash cost (base) | B18: $/t | C18: =Assumptions!C23 -> 45.4 | D18: =Assumptions!D23 -> 47 | E18: =Assumptions!E23 -> 47 | F18: =Assumptions!F23 -> 46
A19: Energy overlay (Iran) | B19: $/t | C19: =MAX(0,(Assumptions!C25-Assumptions!C28)/10*Assumptions!C30) -> 0 | D19: =MAX(0,(Assumptions!D25-Assumptions!C28)/10*Assumptions!C30) -> 0.045 | E19: =MAX(0,(Assumptions!E25-Assumptions!C28)/10*Assumptions!C30) -> 0 | F19: =MAX(0,(Assumptions!F25-Assumptions!C28)/10*Assumptions!C30) -> 0
A20: Total unit cash cost | B20: $/t | C20: =C18+C19 -> 45.4 | D20: =D18+D19 -> 47.045 | E20: =E18+E19 -> 47 | F20: =F18+F19 -> 46
A21: Cash costs | B21: $m | C21: =C15*C20 -> 2760.32 | D21: =D15*D20 -> 2775.655 | E21: =E15*E20 -> 2961 | F21: =F15*F20 -> 2852
A22: Iron ore EBITDA | B22: $m | C22: =C17-C21 -> 2875.84 | D22: =D17-D21 -> 2829.345 | E22: =E17-E21 -> 2709 | F22: =F17-F21 -> 2604
A23: OTHER SEGMENTS
A24: Manganese | B24: $m | C24: =Assumptions!C32 -> 127 | D24: =Assumptions!D32 -> 120 | E24: =Assumptions!E32 -> 120 | F24: =Assumptions!F32 -> 120
A25: Crop Nutrients / Woodsmith | B25: $m | C25: =Assumptions!C33 -> -66 | D25: =Assumptions!D33 -> -75 | E25: =Assumptions!E33 -> -80 | F25: =Assumptions!F33 -> -85
A26: De Beers | B26: $m | C26: =Assumptions!C34 -> -511 | D26: =Assumptions!D34 -> -350 | E26: =Assumptions!E34 -> 0 | F26: =Assumptions!F34 -> 0
A27: Corporate & other | B27: $m | C27: =Assumptions!C35 -> 11 | D27: =Assumptions!D35 -> -50 | E27: =Assumptions!E35 -> -50 | F27: =Assumptions!F35 -> -50
A28: GROUP UNDERLYING EBITDA | B28: $m | C28: =C13+C22+C24+C25+C26+C27 -> 6420.58 | D28: =D13+D22+D24+D25+D26+D27 -> 9490.665 | E28: =E13+E22+E24+E25+E26+E27 -> 10637 | F28: =F13+F22+F24+F25+F26+F27 -> 11386.5
A29: EBITDA growth (YoY) | B29: % | C29: - | D29: =D28/C28-1 -> 0.47816319 | E29: =E28/D28-1 -> 0.12078553 | F29: =F28/E28-1 -> 0.070461596
A30: CASH FLOW & NET DEBT
A31: Less: D&A (e) | B31: $m | C31: =-Assumptions!C38 -> -2700 | D31: =-Assumptions!C38 -> -2700 | E31: =-Assumptions!C38 -> -2700 | F31: =-Assumptions!C38 -> -2700
A32: Underlying EBIT | B32: $m | C32: =C28+C31 -> 3720.58 | D32: =D28+D31 -> 6790.665 | E32: =E28+E31 -> 7937 | F32: =F28+F31 -> 8686.5
A33: Opening net debt | B33: $m | C33: =Assumptions!C46 -> 8571 | D33: =Assumptions!C46 -> 8571 | E33: =D44 -> 2840.6674 | F33: =E44 -> -3655.9473
A34: Net interest (e) | B34: $m | C34: =-MAX(0,C33)*Assumptions!C39 -> -428.55 | D34: =-MAX(0,D33)*Assumptions!C39 -> -428.55 | E34: =-MAX(0,E33)*Assumptions!C39 -> -142.03337 | F34: =-MAX(0,F33)*Assumptions!C39 -> 0
A35: Cash tax (e) | B35: $m | C35: =-Assumptions!C40*MAX(0,C32+C34) -> -823.0075 | D35: =-Assumptions!C40*MAX(0,D32+D34) -> -1590.5287 | E35: =-Assumptions!C40*MAX(0,E32+E34) -> -1948.7417 | F35: =-Assumptions!C40*MAX(0,F32+F34) -> -2171.625
A36: Minorities (e) | B36: $m | C36: =-Assumptions!C41*C28 -> -834.6754 | D36: =-Assumptions!C41*D28 -> -1233.7865 | E36: =-Assumptions!C41*E28 -> -1382.81 | F36: =-Assumptions!C41*F28 -> -1480.245
A37: Working capital / other | B37: $m | C37: =Assumptions!C42 -> -200 | D37: =Assumptions!C42 -> -200 | E37: =Assumptions!C42 -> -200 | F37: =Assumptions!C42 -> -200
A38: Less: capex | B38: $m | C38: =-Assumptions!C37 -> -3322 | D38: =-Assumptions!D37 -> -3600 | E38: =-Assumptions!E37 -> -3100 | F38: =-Assumptions!F37 -> -2600
A39: Attributable free cash flow | B39: $m | C39: =C28+C34+C35+C36+C37+C38 -> 812.3471 | D39: =D28+D34+D35+D36+D37+D38 -> 2437.7998 | E39: =E28+E34+E35+E36+E37+E38 -> 3863.415 | F39: =F28+F34+F35+F36+F37+F38 -> 4934.63
A40: Underlying earnings (e) | B40: $m | C40: =Assumptions!C43*MAX(0,C28+C31+C34) -> 915.18434 | D40: =Assumptions!C43*MAX(0,D28+D31+D34) -> 1768.668 | E40: =Assumptions!C43*MAX(0,E28+E31+E34) -> 2167.0007 | F40: =Assumptions!C43*MAX(0,F28+F31+F34) -> 2414.847
A41: Underlying EPS (e) | B41: c | C41: =C40/Assumptions!C44*100 -> 81.205354 | D41: =D40/Assumptions!C44*100 -> 156.93593 | E41: =E40/Assumptions!C44*100 -> 192.28045 | F41: =F40/Assumptions!C44*100 -> 214.27214
...

Sheet Bear
A1: Anglo American — Bear case
A2: $m unless noted. Black = formula; green = link to Assumptions. EBITDA engine: Price x Volume less cash costs (incl. Iran energy overlay).
A4: Line | B4: Unit | C4: 2025A | D4: 2026e | E4: 2027e | F4: 2028e
A5: COPPER
A6: Production | B6: kt | C6: =Assumptions!C13 -> 695 | D6: =Assumptions!D13 -> 700 | E6: =Assumptions!E13 -> 750 | F6: =Assumptions!F13 -> 790
A7: Realised price | B7: $/t | C7: =Assumptions!C9 -> 9500 | D7: =Assumptions!D9 -> 10000 | E7: =Assumptions!E9 -> 8200 | F7: =Assumptions!F9 -> 8000
A8: Revenue | B8: $m | C8: =C6*C7/1000 -> 6602.5 | D8: =D6*D7/1000 -> 7000 | E8: =E6*E7/1000 -> 6150 | F8: =F6*F7/1000 -> 6320
A9: Unit cash cost (base) | B9: $/t | C9: =Assumptions!C14 -> 3768 | D9: =Assumptions!D14 -> 4250 | E9: =Assumptions!E14 -> 4200 | F9: =Assumptions!F14 -> 4150
A10: Energy overlay (Iran) | B10: $/t | C10: =MAX(0,(Assumptions!C27-Assumptions!C28)/10*Assumptions!C29) -> 0 | D10: =MAX(0,(Assumptions!D27-Assumptions!C28)/10*Assumptions!C29) -> 288 | E10: =MAX(0,(Assumptions!E27-Assumptions!C28)/10*Assumptions!C29) -> 228 | F10: =MAX(0,(Assumptions!F27-Assumptions!C28)/10*Assumptions!C29) -> 138
A11: Total unit cash cost | B11: $/t | C11: =C9+C10 -> 3768 | D11: =D9+D10 -> 4538 | E11: =E9+E10 -> 4428 | F11: =F9+F10 -> 4288
A12: Cash costs | B12: $m | C12: =C6*C11/1000 -> 2618.76 | D12: =D6*D11/1000 -> 3176.6 | E12: =E6*E11/1000 -> 3321 | F12: =F6*F11/1000 -> 3387.52
A13: Copper EBITDA | B13: $m | C13: =C8-C12 -> 3983.74 | D13: =D8-D12 -> 3823.4 | E13: =E8-E12 -> 2829 | F13: =F8-F12 -> 2932.48
A14: PREMIUM IRON ORE
A15: Production | B15: Mt | C15: =Assumptions!C22 -> 60.8 | D15: =Assumptions!D22 -> 55 | E15: =Assumptions!E22 -> 59 | F15: =Assumptions!F22 -> 58
A16: Realised price | B16: $/t | C16: =Assumptions!C18 -> 92.7 | D16: =Assumptions!D18 -> 72 | E16: =Assumptions!E18 -> 60 | F16: =Assumptions!F18 -> 55
A17: Revenue | B17: $m | C17: =C15*C16 -> 5636.16 | D17: =D15*D16 -> 3960 | E17: =E15*E16 -> 3540 | F17: =F15*F16 -> 3190
A18: Unit cash cost (base) | B18: $/t | C18: =Assumptions!C23 -> 45.4 | D18: =Assumptions!D23 -> 47 | E18: =Assumptions!E23 -> 47 | F18: =Assumptions!F23 -> 46
A19: Energy overlay (Iran) | B19: $/t | C19: =MAX(0,(Assumptions!C27-Assumptions!C28)/10*Assumptions!C30) -> 0 | D19: =MAX(0,(Assumptions!D27-Assumptions!C28)/10*Assumptions!C30) -> 0.72 | E19: =MAX(0,(Assumptions!E27-Assumptions!C28)/10*Assumptions!C30) -> 0.57 | F19: =MAX(0,(Assumptions!F27-Assumptions!C28)/10*Assumptions!C30) -> 0.345
A20: Total unit cash cost | B20: $/t | C20: =C18+C19 -> 45.4 | D20: =D18+D19 -> 47.72 | E20: =E18+E19 -> 47.57 | F20: =F18+F19 -> 46.345
A21: Cash costs | B21: $m | C21: =C15*C20 -> 2760.32 | D21: =D15*D20 -> 2624.6 | E21: =E15*E20 -> 2806.63 | F21: =F15*F20 -> 2688.01
A22: Iron ore EBITDA | B22: $m | C22: =C17-C21 -> 2875.84 | D22: =D17-D21 -> 1335.4 | E22: =E17-E21 -> 733.37 | F22: =F17-F21 -> 501.99
A23: OTHER SEGMENTS
A24: Manganese | B24: $m | C24: =Assumptions!C32 -> 127 | D24: =Assumptions!D32 -> 120 | E24: =Assumptions!E32 -> 120 | F24: =Assumptions!F32 -> 120
A25: Crop Nutrients / Woodsmith | B25: $m | C25: =Assumptions!C33 -> -66 | D25: =Assumptions!D33 -> -75 | E25: =Assumptions!E33 -> -80 | F25: =Assumptions!F33 -> -85
A26: De Beers | B26: $m | C26: =Assumptions!C34 -> -511 | D26: =Assumptions!D34 -> -350 | E26: =Assumptions!E34 -> 0 | F26: =Assumptions!F34 -> 0
A27: Corporate & other | B27: $m | C27: =Assumptions!C35 -> 11 | D27: =Assumptions!D35 -> -50 | E27: =Assumptions!E35 -> -50 | F27: =Assumptions!F35 -> -50
A28: GROUP UNDERLYING EBITDA | B28: $m | C28: =C13+C22+C24+C25+C26+C27 -> 6420.58 | D28: =D13+D22+D24+D25+D26+D27 -> 4803.8 | E28: =E13+E22+E24+E25+E26+E27 -> 3552.37 | F28: =F13+F22+F24+F25+F26+F27 -> 3419.47
A29: EBITDA growth (YoY) | B29: % | C29: - | D29: =D28/C28-1 -> -0.25181214 | E29: =E28/D28-1 -> -0.26050835 | F29: =F28/E28-1 -> -0.037411643
A30: CASH FLOW & NET DEBT
A31: Less: D&A (e) | B31: $m | C31: =-Assumptions!C38 -> -2700 | D31: =-Assumptions!C38 -> -2700 | E31: =-Assumptions!C38 -> -2700 | F31: =-Assumptions!C38 -> -2700
A32: Underlying EBIT | B32: $m | C32: =C28+C31 -> 3720.58 | D32: =D28+D31 -> 2103.8 | E32: =E28+E31 -> 852.37 | F32: =F28+F31 -> 719.47
A33: Opening net debt | B33: $m | C33: =Assumptions!C46 -> 8571 | D33: =Assumptions!C46 -> 8571 | E33: =D44 -> 5225.3443 | F33: =E44 -> 3909.5559
A34: Net interest (e) | B34: $m | C34: =-MAX(0,C33)*Assumptions!C39 -> -428.55 | D34: =-MAX(0,D33)*Assumptions!C39 -> -428.55 | E34: =-MAX(0,E33)*Assumptions!C39 -> -261.26722 | F34: =-MAX(0,F33)*Assumptions!C39 -> -195.4778
A35: Cash tax (e) | B35: $m | C35: =-Assumptions!C40*MAX(0,C32+C34) -> -823.0075 | D35: =-Assumptions!C40*MAX(0,D32+D34) -> -418.8125 | E35: =-Assumptions!C40*MAX(0,E32+E34) -> -147.7757 | F35: =-Assumptions!C40*MAX(0,F32+F34) -> -130.99805
A36: Minorities (e) | B36: $m | C36: =-Assumptions!C41*C28 -> -834.6754 | D36: =-Assumptions!C41*D28 -> -624.494 | E36: =-Assumptions!C41*E28 -> -461.8081 | F36: =-Assumptions!C41*F28 -> -444.5311
A37: Working capital / other | B37: $m | C37: =Assumptions!C42 -> -200 | D37: =Assumptions!C42 -> -200 | E37: =Assumptions!C42 -> -200 | F37: =Assumptions!C42 -> -200
A38: Less: capex | B38: $m | C38: =-Assumptions!C37 -> -3322 | D38: =-Assumptions!D37 -> -3600 | E38: =-Assumptions!E37 -> -3100 | F38: =-Assumptions!F37 -> -2600
A39: Attributable free cash flow | B39: $m | C39: =C28+C34+C35+C36+C37+C38 -> 812.3471 | D39: =D28+D34+D35+D36+D37+D38 -> -468.0565 | E39: =E28+E34+E35+E36+E37+E38 -> -618.48101 | F39: =F28+F34+F35+F36+F37+F38 -> -151.53695
A40: Underlying earnings (e) | B40: $m | C40: =Assumptions!C43*MAX(0,C28+C31+C34) -> 915.18434 | D40: =Assumptions!C43*MAX(0,D28+D31+D34) -> 465.7195 | E40: =Assumptions!C43*MAX(0,E28+E31+E34) -> 164.32657 | F40: =Assumptions!C43*MAX(0,F28+F31+F34) -> 145.66983
A41: Underlying EPS (e) | B41: c | C41: =C40/Assumptions!C44*100 -> 81.205354 | D41: =D40/Assumptions!C44*100 -> 41.323824 | E41: =E40/Assumptions!C44*100 -> 14.580885 | F41: =F40/Assumptions!C44*100 -> 12.925451
...

Sheet Sensitivity
A1: Sensitivity — Group EBITDA to commodity prices (FY2026e)
A2: Holds Base-case volumes, costs and other segments for 2026e; flexes one price at a time. $m.
A4: Copper price ($/t) | B4: Copper EBITDA ($m) | C4: Group EBITDA ($m)
A5: 7000 | B5: =Base!D6*(A5-Base!D11)/1000 -> 1928.66 | C5: =B5+(Base!D22+Base!D24+Base!D25+Base!D26+Base!D27) -> 3724.27
A6: 8000 | B6: =Base!D6*(A6-Base!D11)/1000 -> 2658.66 | C6: =B6+(Base!D22+Base!D24+Base!D25+Base!D26+Base!D27) -> 4454.27
A7: 9000 | B7: =Base!D6*(A7-Base!D11)/1000 -> 3388.66 | C7: =B7+(Base!D22+Base!D24+Base!D25+Base!D26+Base!D27) -> 5184.27
A8: 10000 | B8: =Base!D6*(A8-Base!D11)/1000 -> 4118.66 | C8: =B8+(Base!D22+Base!D24+Base!D25+Base!D26+Base!D27) -> 5914.27
A9: 11000 | B9: =Base!D6*(A9-Base!D11)/1000 -> 4848.66 | C9: =B9+(Base!D22+Base!D24+Base!D25+Base!D26+Base!D27) -> 6644.27
A10: 12000 | B10: =Base!D6*(A10-Base!D11)/1000 -> 5578.66 | C10: =B10+(Base!D22+Base!D24+Base!D25+Base!D26+Base!D27) -> 7374.27
A11: 13000 | B11: =Base!D6*(A11-Base!D11)/1000 -> 6308.66 | C11: =B11+(Base!D22+Base!D24+Base!D25+Base!D26+Base!D27) -> 8104.27
A12: 14000 | B12: =Base!D6*(A12-Base!D11)/1000 -> 7038.66 | C12: =B12+(Base!D22+Base!D24+Base!D25+Base!D26+Base!D27) -> 8834.27
A13: 15000 | B13: =Base!D6*(A13-Base!D11)/1000 -> 7768.66 | C13: =B13+(Base!D22+Base!D24+Base!D25+Base!D26+Base!D27) -> 9564.27
A15: Iron ore price ($/t) | B15: Iron ore EBITDA ($m) | C15: Group EBITDA ($m)
A16: 50 | B16: =Base!D15*(A16-Base!D20) -> 155.61 | C16: =B16+(Base!D13+Base!D24+Base!D25+Base!D26+Base!D27) -> 5014.27
A17: 60 | B17: =Base!D15*(A17-Base!D20) -> 725.61 | C17: =B17+(Base!D13+Base!D24+Base!D25+Base!D26+Base!D27) -> 5584.27
A18: 70 | B18: =Base!D15*(A18-Base!D20) -> 1295.61 | C18: =B18+(Base!D13+Base!D24+Base!D25+Base!D26+Base!D27) -> 6154.27
A19: 80 | B19: =Base!D15*(A19-Base!D20) -> 1865.61 | C19: =B19+(Base!D13+Base!D24+Base!D25+Base!D26+Base!D27) -> 6724.27
A20: 90 | B20: =Base!D15*(A20-Base!D20) -> 2435.61 | C20: =B20+(Base!D13+Base!D24+Base!D25+Base!D26+Base!D27) -> 7294.27
A21: 100 | B21: =Base!D15*(A21-Base!D20) -> 3005.61 | C21: =B21+(Base!D13+Base!D24+Base!D25+Base!D26+Base!D27) -> 7864.27
A22: 110 | B22: =Base!D15*(A22-Base!D20) -> 3575.61 | C22: =B22+(Base!D13+Base!D24+Base!D25+Base!D26+Base!D27) -> 8434.27

Sheet Teck overlay
A1: Anglo Teck — merger overlay (illustrative, pre-completion)
A2: Not consolidated guidance. Standalone Anglo (Base) plus Teck contribution + synergies. Close expected Sep 2026–Mar 2027. $m unless noted.
A4: KEY TERMS
A5: Exchange ratio (Anglo sh / Teck sh) | B5: =Assumptions!C58 -> 1.3301
A6: Ownership — Anglo holders | B6: =Assumptions!C59 -> 0.624
A7: Ownership — Teck holders | B7: =Assumptions!C60 -> 0.376
A8: Special dividend to Anglo holders ($m) | B8: =Assumptions!C61 -> 4500
A9: Run-rate pre-tax synergies, by yr4 ($m) | B9: =Assumptions!C62 -> 800
A10: One-off cost to achieve ($m) | B10: =Assumptions!C63 -> 700
A11: ILLUSTRATIVE PRO-FORMA EBITDA
B12: 2027e | C12: 2028e
A13: Anglo standalone EBITDA (Base) | B13: =Base!E28 -> 6360.24 | C13: =Base!F28 -> 6734.54
A14: Teck EBITDA contribution (e) | B14: =Assumptions!C64 -> 2150 | C14: =Assumptions!C64*1.05 -> 2257.5
A15: Synergy phase-in (e: 20% / 50%) | B15: =Assumptions!C62*0.2 -> 160 | C15: =Assumptions!C62*0.5 -> 400
A16: Pro-forma Anglo Teck EBITDA (e) | B16: =B13+B14+B15 -> 8670.24 | C16: =C13+C14+C15 -> 9392.04
A18: Combined copper production (~Mt): 1.2Mt now → ~1.35Mt 2027. Copper >70% of group. HQ Vancouver; primary listing LSE.
A19: Special dividend ($4.5bn) is a one-off cash return funded partly by disposals; raises pro-forma net debt at completion, offset by Teck's balance sheet.

Sheet Sources
A1: Sources
A2: Description | B2: URL
A3: Anglo American FY2025 results (RNS, Investegate) | B3: https://www.investegate.co.uk/announcement/rns/anglo-american--aal/anglo-american-full-year-2025-results/9439268
A4: Anglo American FY2025 preliminary results PDF | B4: https://www.angloamerican.com/~/media/Files/A/Anglo-American-Group-v9/PLC/media/press-release/releases/2026pr/anglo-american-preliminary-results-for-the-year-ended-31-december-2025.pdf
A5: Anglo American Q4 2025 production report (guidance) | B5: https://www.angloamerican.com/media/press-releases/2026/05-02-2026
A6: Mining Weekly — 2026 copper guidance cut (5 Feb 2026) | B6: https://www.miningweekly.com/article/anglo-lowers-2026-copper-production-guidance-following-lower-2025-output-2026-02-05
A7: Anglo Teck merger of equals (announcement, 9 Sep 2025) | B7: https://www.angloamerican.com/media/press-releases/2025/09-09-2025
A8: Anglo Teck — SEC Exhibit 99.1 (synergies/cost to achieve) | B8: https://www.sec.gov/Archives/edgar/data/886986/000095014225002410/eh250676348_ex9901.htm
A9: Anglo Teck merger — completion timing (Mining.com) | B9: https://www.mining.com/web/anglo-american-expects-final-approval-for-teck-merger-around-q3/
A10: Anglo — sell coal to Dhilmar up to $3.88bn (Reuters, 18 May 2026) | B10: https://www.reuters.com/business/energy/anglo-american-sell-australian-coal-mines-up-388-billion-2026-05-18/
A11: De Beers sale process / Botswana (Mining.com, 5 Jun 2026) | B11: https://www.mining.com/anglo-american-draws-botswana-into-5b-de-beers-sale-talks/
A12: World Bank Commodity Markets Outlook, April 2026 | B12: https://www.worldbank.org/en/news/press-release/2026/04/28/commodity-markets-outlook-april-2026-press-release
A13: World Bank — metals to strengthen (copper) | B13: https://blogs.worldbank.org/en/opendata/metal-prices-poised-to-strengthen-further
... A21: LSE AAL share price (12 Jun 2026) | B21: https://www.lse.co.uk/SharePrice.html?shareprice=AAL&share=Anglo-american
